Workbook
Name _Toc40480675: 'Cal.(DW)'!$C$157
Name AJB_12T: #REF!
Name coupon: #REF!
Name coupon: #REF!
Name cpts: #REF!
Name cpts: #REF!
Name DPTS: #REF!
Name fence100: #REF!
Name fence100: #REF!
Name fence48: #REF!
Name fence48: #REF!
Name fence60: #REF!
Name fence60: #REF!
Name hdd100lb: #REF!
Name hdd100lb: #REF!
Name hdd48lb: #REF!
Name hdd48lb: #REF!
Name hdd60lb: #REF!
Name hdd60lb: #REF!
Name Isolation: #REF!
Name Isolation: #REF!
Name linec: #REF!
Name linec: #REF!
Name NJB_5T: #REF!
Name OHL: #REF!
Name OHL: #REF!
Name Parapl: #REF!
Name Parapl: #REF!
Name Parapl3t: #REF!
Name Parapl5t: #REF!
Name PLcros2t: #REF!
Name PLcros2t: #REF!
Name PLcros3t: #REF!
Name PLcros3t: #REF!
Name PLcros5t: #REF!
Name PLcros5t: #REF!
Name PLpara: #REF!
Name PLpara: #REF!
Name road100: #REF!
Name road100: #REF!
Name road1pin: #REF!
Name road1pin: #REF!
Name road48: #REF!
Name road48: #REF!
Name road60: #REF!
Name road60: #REF!
Name singlepin: #REF!
Name singlepin: #REF!
Name smart: #REF!
Name smart: #REF!
Name TCP60lb: #REF!
Name TCP60lb: #REF!
Name thrust60lb: #REF!
Name thrust60lb: #REF!
Name TL100lb: #REF!
Name tl48lb: #REF!
Name tl60lb: #REF!
Name TRU_100V25A: #REF!
Name valve: #REF!
Name valve: #REF!

Sheet Cal.(DW)
A1: PERMANENT CP SYSTEM CALCULATIONS
A2: ICCP System Description
A3: 1 | B3: Client | C3: ECP25-0292-ICCP HAJAR IPP
A4: 2 | B4: End Client | C4: -
A5: 4 | B5: Project Name | C5: PERMANENT CATHODIC PROTECTION OF HAJAR IPP
A6: 3 | B6: Pipeline Name | C6: 48" Gas Sales P/L -Tie In
C7: 48" Gas Sales P/L-Main
A9: S.No. | B9: Description | C9: Symbols | E9: Unit | F9: =C6 -> 48" Gas Sales P/L -Tie In | G9: =C7 -> 48" Gas Sales P/L-Main
A10: 1) PIPELINE DESIGN PARAM. & CURRENT REQUIRMENTS
B11: Pipeline Input Details
A12: 1.1 | B12: Pipeline Diameter | C12: - | E12: inch | F12: 48 | G12: 48
A13: 1.2 | B13: Pipeline Diameter | C13: D | E13: m | F13: =F12/39.37 -> 1.2192024 | G13: =G12/39.37 -> 1.2192024
A14: 1.3 | B14: Pipeline Thickness | E14: inch | F14: 0.875 | G14: 0.875
A15: 1.4 | B15: Operating Temperature | C15: - | E15: Deg °C | F15: 57.22 | G15: 57.22
B16: Pipeline Current req. Cal.
A17: 1.5 | B17: Pipeline Section Start | C17: - | E17: m | F17: 0 | G17: 0
A18: 1.6 | B18: Pipeline Section end | C18: - | E18: m | F18: 292 | G18: 41480
A19: 1.7 | B19: Pipeline Section length | C19: L | E19: m | F19: =F18-F17 -> 292 | G19: =G18-G17 -> 41480
A20: 1.8 | B20: Current density | C20: - | E20: mA/sq.m | F20: 0.1 | G20: 0.1
A21: 1.9 | B21: Pipeline Surface area | C21: A | E21: Sq.m | F21: =3.14*(F19*F13) -> 1117.8623 | G21: =3.14*(G19*G13) -> 158797.7
A22: 1.1 | B22: Current density at operating temperature | C22: i | E22: mA /sq.m | F22: =F20*1.25^((F15-30)/10) -> 0.18356465 | G22: =G20*1.25^((G15-30)/10) -> 0.18356465
A23: 1.11 | B23: Total Current required for PCP | C23: Ireq. | E23: Amps. | F23: =F21*F22/1000 -> 0.20520001 | G23: =G21*G22/1000 -> 29.149645
A24: 1.12 | B24: Total current required at 30% spare ( Pipeline Current Req. +30% Spare Current) | C24: Ireq. | F24: =F23*1.3 -> 0.26676001 | G24: =G23*1.3 -> 37.894539
A26: 2) Anode Requirement ParaM. (High-Silicon Cast Iron TA-4)
A27: S.No. | B27: Description | C27: Symbols | E27: Unit | F27: ICCP Sation-1 @KM 00+000 (Launcher) | I27: ICCP Sation-2 @KM 41+488 (At Scraper Receiver)
A28: 2.1 | B28: ICCP Anode type | F28: High-Silicon Cast Iron (TA-4) | I28: High-Silicon Cast Iron (TA-4)
A29: 2.2 | B29: Total current required at 30% spare | C29: Ireq. | E29: Amp. | F29: =(F24+G24)*0.5 -> 19.080649 | I29: =(F24+G24)*0.5 -> 19.080649
A30: 2.3 | B30: Anode current output (3.56A for TA4 for 25 years) | C30: Ia | E30: Amp. | F30: 3.56 | I30: 3.56
A31: 2.4 | B31: No. of anodes based on current | E31: Each | F31: =ROUNDUP(F29/F30,0) -> 6 | I31: =ROUNDUP(I29/I30,0) -> 6
A32: 2.4 | B32: TR current rating** | C32: Ir | E32: Amps | F32: 25 | I32: 35
A33: 2.5 | B33: No of anodes based on TR rating | E33: Each | F33: =F32/F30 -> 7.0224719 | I33: =I32/I30 -> 9.8314607
A34: 2.6 | B34: Proposed Anode | E34: Each | F34: 9 | I34: 12
A36: 3) Cathodic Protection System Lifetime
A37: S.No. | B37: Description | C37: Symbols | E37: Unit | F37: =F27 -> ICCP Sation-1 @KM 00+000 (Launcher) | I37: =I27 -> ICCP Sation-2 @KM 41+488 (At Scraper Receiver)
A38: 3.1 | B38: Proposed Number of Anodes | C38: N | E38: Ea | F38: =F34 -> 9 | I38: =I34 -> 12
A39: 3.2 | B39: Single Anode Weight | C39: W | E39: kg | F39: 38.6 | I39: 38.6
A40: 3.3 | B40: Consumption Rate | C40: C | E40: Kg/A-Y | F40: 0.45 | I40: 0.45
A41: 3.4 | B41: TR current rating(Amps) | C41: Ir | E41: A | F41: =F32 -> 25 | I41: =I32 -> 35
A42: 3.5 | B42: Design Life time > 25 | C42: Y | E42: Y | F42: =(F38*F39*0.85)/(F41*F40) -> 26.248 | I42: =(I38*I39*0.85)/(I41*I40) -> 24.998095
A43: 3.6 | B43: Proposed anodes are complying with 25 years design life | F43: Yes | I43: Yes
...

Sheet BOM-(DW)
E1: V | G1: ='Cal.(DW)'!F167 -> 30
E2: A | G2: ='Cal.(DW)'!F168 -> 25
E3: VA | G3: 100V/25A
E4: AGB | G4: 1
E5: Anode | G5: {='Cal.(DW)'!F34:G34} -> 9 | H5: 0
E6: In-active | G6: ='Cal.(DW)'!F48 -> 15
E7: active | G7: ='Cal.(DW)'!F55 -> 35
A8: BUDGETARY BILL OF MATERIAL FOR PERMANENT CP SYSTEM | G8: 1
A9: ITEM | B9: ITEM | C9: D E S C R I P T I O N | D9: SAMS NUMBER | E9: UNIT | F9: Total | G9: ='Cal.(DW)'!F27 -> ICCP Sation-1 @KM 00+000 (Launcher) | I9: Yes
A10: BILL OF MATERIAL FOR TRU | I10: Yes
A11: 1 | B11: 1 | C11: Transformer Rectifier; Manual Controlled (Conventional), Oil Cooled, 480V/3P/60Hz AC Input 100V/35A DC Output, NEMA4X Enclosure C/W Sunshade, conduit with End bushing as per Saudi ARAMCO Standard. 17-SAMSS-004, Equipped with Potential Free Contact for AC Failure Alarm. | D11: 17-SAMSS-00 | E11: Each | F11: =SUM(G11:G11) -> 0 | G11: 0 | I11: =IF(ISNUMBER(G11) * (G11 > 0), "Yes", "No") -> No
C12: Transformer Rectifier; Manual Controlled (Conventional), Oil Cooled, 480V/3P/60Hz AC Input 30V/25A DC Output, NEMA4X Enclosure C/W Sunshade, conduit with End bushing as per Saudi ARAMCO Standard. 17-SAMSS-004, Equipped with Potential Free Contact for AC Failure Alarm. | D12: 17-SAMSS-01 | E12: Each | F12: =SUM(G12:G12) -> 1 | G12: 1 | I12: =IF(ISNUMBER(G12) * (G12 > 0), "Yes", "No") -> Yes
C13: Transformer Rectifier; Manual Controlled (Conventional), Oil Cooled, 480V/3P/60Hz AC Input 50V/25A DC Output, NEMA4X Enclosure C/W Sunshade, conduit with End bushing as per Saudi ARAMCO Standard. 17-SAMSS-004, Equipped with Potential Free Contact for AC Failure Alarm. | D13: 17-SAMSS-00 | E13: Each | F13: =SUM(G13:G13) -> 0 | G13: 0 | I13: =IF(ISNUMBER(G13) * (G13 > 0), "Yes", "No") -> No
C14: Transformer Rectifier; Manual Controlled (Conventional), Oil Cooled, 480V/3P/60Hz AC Input 50V/50A DC Output, NEMA4X Enclosure C/W Sunshade, conduit with End bushing as per Saudi ARAMCO Standard. 17-SAMSS-004, Equipped with Potential Free Contact for AC Failure Alarm. | D14: 17-SAMSS-00 | E14: Each | F14: =SUM(G14:G14) -> 0 | G14: 0 | I14: =IF(ISNUMBER(G14) * (G14 > 0), "Yes", "No") -> No
C15: Transformer Rectifier; Manual Controlled (Conventional), Oil Cooled, 480V/3P/60Hz AC Input100V/50A DC Output, NEMA4X Enclosure C/W Sunshade, conduit with End bushing as per Saudi ARAMCO Standard. 17-SAMSS-004, Equipped with Potential Free Contact for AC Failure Alarm. | D15: 17-SAMSS-00 | E15: Each | F15: =SUM(G15:G15) -> 0 | G15: 0 | I15: =IF(ISNUMBER(G15) * (G15 > 0), "Yes", "No") -> No
C16: Transformer Rectifier; Manual Controlled (Conventional), Oil Cooled, 480V/3P/60Hz AC Input100V/75A DC Output, NEMA4X Enclosure C/W Sunshade, conduit with End bushing as per Saudi ARAMCO Standard. 17-SAMSS-004, Equipped with Potential Free Contact for AC Failure Alarm. | D16: 17-SAMSS-00 | E16: Each | F16: =SUM(G16:G16) -> 0 | G16: 0 | I16: =IF(ISNUMBER(G16) * (G16 > 0), "Yes", "No") -> No
A17: 2 | C17: CP RMU Type-A(For TRU) as per 17-SAMSS-018 | F17: =SUM(G17:G17) -> 1 | G17: =SUM(G11:G16) -> 1
A18: 3 | B18: 2 | C18: Transformer Oil (208 Liters / Drum) | D18: - | E18: Drum | F18: =SUM(G18:G18) -> 2 | G18: =SUM(G11:G16)*2 -> 2 | I18: =IF(ISNUMBER(G18) * (G18 > 0), "Yes", "No") -> Yes
A19: 4 | B19: 3 | C19: Three Phase 480V, AC Disconnecting Switch c/w conduit & support | D19: - | E19: Each | F19: =SUM(G19:G19) -> 1 | G19: =SUM(G11:G16) -> 1 | I19: =IF(ISNUMBER(G19) * (G19 > 0), "Yes", "No") -> Yes
A20: BILL OF MATERIAL FOR POSITIVE CIRCUIT | I20: Yes
A21: 5 | B21: 4 | C21: ="Anode-1, HSCI, Tubular, TA-4 c/w -" & 'Cal.(DW)'!F79 & " M 16mm² PVDF/HMWPE Cable" -> Anode-1, HSCI, Tubular, TA-4 c/w -25 M 16mm² PVDF/HMWPE Cable | D21: 17-852-308 | E21: Each | F21: =SUM(G21:G21) -> 1 | G21: 1 | I21: =IF(ISNUMBER(G21) * (G21 > 0), "Yes", "No") -> Yes
C22: ="Anode-1, HSCI, Tubular, TA-4 c/w -" & 'Cal.(DW)'!F80 & " M 16mm² PVDF/HMWPE Cable" -> Anode-1, HSCI, Tubular, TA-4 c/w -30 M 16mm² PVDF/HMWPE Cable | D22: 17-852-308 | E22: Each | F22: =SUM(G22:G22) -> 1 | G22: 1 | I22: =IF(ISNUMBER(G22) * (G22 > 0), "Yes", "No") -> Yes
C23: ="Anode-1, HSCI, Tubular, TA-4 c/w -" & 'Cal.(DW)'!F81 & " M 16mm² PVDF/HMWPE Cable" -> Anode-1, HSCI, Tubular, TA-4 c/w -35 M 16mm² PVDF/HMWPE Cable | D23: 17-852-308 | E23: Each | F23: =SUM(G23:G23) -> 1 | G23: 1 | I23: =IF(ISNUMBER(G23) * (G23 > 0), "Yes", "No") -> Yes
C24: ="Anode-1, HSCI, Tubular, TA-4 c/w -" & 'Cal.(DW)'!F82 & " M 16mm² PVDF/HMWPE Cable" -> Anode-1, HSCI, Tubular, TA-4 c/w -40 M 16mm² PVDF/HMWPE Cable | D24: 17-852-308 | E24: Each | F24: =SUM(G24:G24) -> 1 | G24: 1 | I24: =IF(ISNUMBER(G24) * (G24 > 0), "Yes", "No") -> Yes
C25: ="Anode-1, HSCI, Tubular, TA-4 c/w -" & 'Cal.(DW)'!F83 & " M 16mm² PVDF/HMWPE Cable" -> Anode-1, HSCI, Tubular, TA-4 c/w -45 M 16mm² PVDF/HMWPE Cable | D25: 17-852-308 | E25: Each | F25: =SUM(G25:G25) -> 1 | G25: 1 | I25: =IF(ISNUMBER(G25) * (G25 > 0), "Yes", "No") -> Yes
C26: ="Anode-1, HSCI, Tubular, TA-4 c/w -" & 'Cal.(DW)'!F84 & " M 16mm² PVDF/HMWPE Cable" -> Anode-1, HSCI, Tubular, TA-4 c/w -50 M 16mm² PVDF/HMWPE Cable | D26: 17-852-308 | E26: Each | F26: =SUM(G26:G26) -> 1 | G26: 1 | I26: =IF(ISNUMBER(G26) * (G26 > 0), "Yes", "No") -> Yes
C27: ="Anode-1, HSCI, Tubular, TA-4 c/w -" & 'Cal.(DW)'!F85 & " M 16mm² PVDF/HMWPE Cable" -> Anode-1, HSCI, Tubular, TA-4 c/w -55 M 16mm² PVDF/HMWPE Cable | D27: 17-852-308 | E27: Each | F27: =SUM(G27:G27) -> 1 | G27: 1 | I27: =IF(ISNUMBER(G27) * (G27 > 0), "Yes", "No") -> Yes
C28: ="Anode-1, HSCI, Tubular, TA-4 c/w -" & 'Cal.(DW)'!F86 & " M 16mm² PVDF/HMWPE Cable" -> Anode-1, HSCI, Tubular, TA-4 c/w -60 M 16mm² PVDF/HMWPE Cable | D28: 17-852-308 | E28: Each | F28: =SUM(G28:G28) -> 1 | G28: 1 | I28: =IF(ISNUMBER(G28) * (G28 > 0), "Yes", "No") -> Yes
C29: ="Anode-1, HSCI, Tubular, TA-4 c/w -" & 'Cal.(DW)'!F87 & " M 16mm² PVDF/HMWPE Cable" -> Anode-1, HSCI, Tubular, TA-4 c/w -65 M 16mm² PVDF/HMWPE Cable | D29: 17-852-308 | E29: Each | F29: =SUM(G29:G29) -> 1 | G29: 1 | I29: =IF(ISNUMBER(G29) * (G29 > 0), "Yes", "No") -> Yes
C30: ="Anode-1, HSCI, Tubular, TA-4 c/w -" & 'Cal.(DW)'!F88 & " M 16mm² PVDF/HMWPE Cable" -> Anode-1, HSCI, Tubular, TA-4 c/w - M 16mm² PVDF/HMWPE Cable | D30: 17-852-308 | E30: Each | F30: =SUM(G30:G30) -> 0 | I30: =IF(ISNUMBER(G30) * (G30 > 0), "Yes", "No") -> No
C31: ="Anode-1, HSCI, Tubular, TA-4 c/w -" & 'Cal.(DW)'!F89 & " M 16mm² PVDF/HMWPE Cable" -> Anode-1, HSCI, Tubular, TA-4 c/w - M 16mm² PVDF/HMWPE Cable | D31: 17-852-308 | E31: Each | F31: =SUM(G31:G31) -> 0 | I31: =IF(ISNUMBER(G31) * (G31 > 0), "Yes", "No") -> No
C32: ="Anode-1, HSCI, Tubular, TA-4 c/w -" & 'Cal.(DW)'!F90 & " M 16mm² PVDF/HMWPE Cable" -> Anode-1, HSCI, Tubular, TA-4 c/w - M 16mm² PVDF/HMWPE Cable | D32: 17-852-308 | E32: Each | F32: =SUM(G32:G32) -> 0 | I32: =IF(ISNUMBER(G32) * (G32 > 0), "Yes", "No") -> No
A33: =IF(OR(G33="-", G19<=0), "", MAX($A$11:A32)+1) -> 6 | B33: 5 | C33: Cable -35mm² Single core PVDF/HMWPE Insulated | D33: 17-SAMSS-017 | E33: M | F33: =SUM(G33:G33) -> 180 | G33: 180 | I33: =IF(ISNUMBER(G33) * (G33 > 0), "Yes", "No") -> Yes
A34: 7 | C34: 20 – Terminal Anode Junction Box | D34: 17-SAMSS-008 | E34: Each | F34: =SUM(G34:G34) -> 0 | G34: 0 | I34: =IF(ISNUMBER(G34) * (G34 > 0), "Yes", "No") -> No
B35: 6 | C35: 12 – Terminal Anode Junction Box | D35: 17-SAMSS-008 | E35: Each | F35: =SUM(G35:G35) -> 1 | G35: 1 | I35: =IF(ISNUMBER(G35) * (G35 > 0), "Yes", "No") -> Yes
C36: Multi-Purpose Junction Box as per Aramco Std. Drg. 36276 | D36: 17-SAMSS-008 | E36: Each | F36: =SUM(G36:G36) -> 0 | G36: =IF(G4>1, 1, 0) -> 0 | I36: =IF(ISNUMBER(G36) * (G36 > 0), "Yes", "No") -> No
A37: 8 | C37: Marker Plate, as per aramco Std. Drg. AA-036351 for Anode junction box | E37: Each | F37: =SUM(G37:G37) -> 1 | G37: =G35+G36 -> 1
A38: =IF(OR(G37="-", G37<=0), "", MAX($A$11:A40)+1) | C38: Marker Plate, as per aramco Std. Drg. AA-036351 for Multi-Purpose Junction Box | E38: Each | F38: =SUM(G38:G38) -> 0 | G38: =G36 -> 0
A39: BILL OF MATERIAL FOR NEGATIVE CIRCUIT | I39: Yes
A40: 9 | B40: 7 | C40: 5T NEGATIVE JUNCTION BOX- C/W Support& Conduit and Marker Plate as per Aramco std. Dwg. AB-036274 | D40: 17-SAMSS-008 | E40: Each | F40: =SUM(G40:G40) -> 1 | G40: 1 | I40: =IF(ISNUMBER(G40) * (G40 > 0), "Yes", "No") -> Yes
...

Sheet BOM-(HA)
A1: BILL OF MATERIAL FOR PERMANENT CP SYSTEM
A2: ITEM | B2: D E S C R I P T I O N | C2: SAMS NUMBER | D2: UNIT | E2: ICCP System#02 | F2: Remarks
A3: BILL OF MATERIAL FOR TRU
A4: 1 | B4: Transformer Rectifier; Manual Controlled (Conventional), Oil Cooled, 480V/3P/60Hz AC Input, 50V/35A DC Output, NEMA4X Enclosure C/W Sunshade, conduit with End bushing as per Saudi ARAMCO Standard. 17-SAMSS-004, Equipped with Potential Free Contact for AC Failure Alarm. | C4: 17-SAMSS-00 | D4: Each | E4: 1 | G4: =IF(E4 > 0, "Yes", "No") -> Yes
A5: 2 | B5: CP RMU Type-A(For TRU) as per 17-SAMSS-018 | D5: Each | E5: 1 | G5: =IF(E5 > 0, "Yes", "No") -> Yes
A6: =IF(OR(E6="-", E6<=0), "", MAX($A$4:A4)+1) -> 2 | B6: Transformer Oil (208 Liters / Drum) | C6: - | D6: Drum | E6: 1 | G6: =IF(E6 > 0, "Yes", "No") -> Yes
A7: =IF(OR(E7="-", E7<=0), "", MAX($A$4:A6)+1) -> 3 | B7: Three Phase 480V, AC Disconnecting Switch c/w conduit & support | C7: - | D7: Each | E7: 1 | G7: =IF(E7 > 0, "Yes", "No") -> Yes
A8: BILL OF MATERIAL FOR POSITIVE CIRCUIT | G8: Yes
A9: =IF(OR(E9:E16="-", E9<=0), "", MAX($A$4:A7)+1) -> 4 | B9: Anode-1, HSCI, Tubular, TA-4 c/w - 40 M 16mm² PVDF/HMWPE Cable | C9: 17-852-308 | D9: Each | E9: 1 | G9: =IF(E9 > 0, "Yes", "No") -> Yes
B10: Anode-2, HSCI, Tubular, TA-4 c/w - 40 M 16mm² PVDF/HMWPE Cable | C10: 17-852-308 | D10: Each | E10: 1 | G10: =IF(E10 > 0, "Yes", "No") -> Yes
B11: Anode-3, HSCI, Tubular, TA-4 c/w - 40 M 16mm² PVDF/HMWPE Cable | C11: 17-852-308 | D11: Each | E11: 1 | G11: =IF(E11 > 0, "Yes", "No") -> Yes
B12: Anode-4, HSCI, Tubular, TA-4 c/w - 40 M 16mm² PVDF/HMWPE Cable | C12: 17-852-308 | D12: Each | E12: 1 | G12: =IF(E12 > 0, "Yes", "No") -> Yes
B13: Anode-5, HSCI, Tubular, TA-4 c/w - 30 M 16mm² PVDF/HMWPE Cable | C13: 17-852-308 | D13: Each | E13: 1 | G13: =IF(E13 > 0, "Yes", "No") -> Yes
B14: Anode-6, HSCI, Tubular, TA-4 c/w - 30 M 16mm² PVDF/HMWPE Cable | C14: 17-852-308 | D14: Each | E14: 1 | G14: =IF(E14 > 0, "Yes", "No") -> Yes
B15: Anode-7, HSCI, Tubular, TA-4 c/w - 30 M 16mm² PVDF/HMWPE Cable | C15: 17-852-308 | D15: Each | E15: 1 | G15: =IF(E15 > 0, "Yes", "No") -> Yes
B16: Anode-8, HSCI, Tubular, TA-4 c/w - 30 M 16mm² PVDF/HMWPE Cable | C16: 17-852-308 | D16: Each | E16: 1 | G16: =IF(E16 > 0, "Yes", "No") -> Yes
B17: Anode-9, HSCI, Tubular, TA-4 c/w - 40 M 16mm² PVDF/HMWPE Cable | C17: 17-852-308 | D17: Each | E17: 1 | G17: =IF(E17 > 0, "Yes", "No") -> Yes
B18: Anode-10, HSCI, Tubular, TA-4 c/w - 40 M 16mm² PVDF/HMWPE Cable | C18: 17-852-308 | D18: Each | E18: 1
B19: Anode-11, HSCI, Tubular, TA-4 c/w - 40 M 16mm² PVDF/HMWPE Cable | C19: 17-852-308 | D19: Each | E19: 1
B20: Anode-12, HSCI, Tubular, TA-4 c/w - 40 M 16mm² PVDF/HMWPE Cable | C20: 17-852-308 | D20: Each | E20: 1
A21: =IF(OR(E21="-", E7<=0), "", MAX($A$4:A17)+1) -> 5 | B21: Cable -35mm² Single core PVDF/HMWPE Insulated | C21: 17-SAMSS-017 | D21: M | E21: 160 | G21: =IF(E21 > 0, "Yes", "No") -> Yes
A22: =IF(OR(E22="-", E22<=0), "", MAX($A$4:A21)+1) -> 6 | B22: 12 – Terminal Anode Junction Box c/w support & conduits Aramco and Marker Plate Dwg. 036275 | C22: 17-SAMSS-008 | D22: Each | E22: 1 | G22: =IF(E22 > 0, "Yes", "No") -> Yes
A23: =IF(OR(E23="-", E23<=0), "", MAX($A$4:A22)+1) | B23: Marker Plate, as per aramco Std. Drg. AA-036351 for Anode junction box | G23: =IF(E23 > 0, "Yes", "No") -> No
A24: BILL OF MATERIAL FOR NEGATIVE CIRCUIT | G24: Yes
A25: 7 | B25: 5T NEGATIVE JUNCTION BOX- C/W Support& Conduit and Marker Plate as per Aramco std. Dwg. AB-036274 | C25: 17-SAMSS-008 | D25: Each | E25: 1 | G25: =IF(E25 > 0, "Yes", "No") -> Yes
A26: 8 | B26: Marker Plate, as per aramco Std. Drg. AA-036351 for Negative Junction Box | E26: 1 | G26: =IF(E26 > 0, "Yes", "No") -> Yes
A27: 9 | B27: Cable -25mm² Single core HMWPE Insulated | C27: 17-SAMSS-017 | D27: M | E27: 60 | G27: =IF(E27 > 0, "Yes", "No") -> Yes
A28: 10 | B28: Cable -35mm² Single core HMWPE Insulated | C28: 17-SAMSS-017 | D28: M | E28: 150 | G28: =IF(E28 > 0, "Yes", "No") -> Yes
A29: 11 | B29: Cable -10mm² Single core THHN/ THWN-Measuring connection cable(to RTU) | C29: - | D29: Roll | E29: 1 | G29: =IF(E29 > 0, "Yes", "No") -> Yes | H29: IR-Free Probe with one Test Coupons and
A30: 12 | B30: Solid State Stationary Reference Electrode Cu-CuSO4 C/W 6mm THHN/THWN, 150M Length. (STELTH 2-Model SRE-007-CUY) | C30: - | D30: Each | E30: 1 | G30: =IF(E30 > 0, "Yes", "No") -> Yes
A31: 13 | B31: Single pin Test Station (For Drain Point) as per Aramco Drawing AB-036907 C/W Support, Conduit, and SS tag "Drain point test station". | D31: Each | E31: 1 | G31: =IF(E31 > 0, "Yes", "No") -> Yes
A32: 14 | B32: Cable -10mm² Single core THHN/ THWN-Measuring connection cable(Drain Point TS) | D32: Roll | E32: 0.067 | G32: =IF(E32 > 0, "Yes", "No") -> Yes
A33: 15 | B33: Thermo weld Mold for CA-15 | C33: 20-512-215 | D33: Ea. | E33: 1 | G33: =IF(E33 > 0, "Yes", "No") -> Yes
A34: 16 | B34: Thermo weld charges CA-15 | C34: 20-476-803 | D34: Charge | E34: 25 | G34: =IF(E34 > 0, "Yes", "No") -> Yes
A35: 17 | B35: Primer Solvent welding, PVC to PVC(250ml/can) | C35: - | D35: Can | E35: 2 | G35: =IF(E35 > 0, "Yes", "No") -> Yes
A36: 18 | B36: Marker Plate, as per aramco Std. Drg. AA-036351 for Negative Junction Box | G36: =IF(E36 > 0, "Yes", "No") -> No
A37: BILL OF MATERIAL FOR MESELENIOUS ITEMS | G37: =IF(E37 > 0, "Yes", "No") -> No
A38: 19 | B38: Calcined Petroleum Coke Backfill | C38: 17-855-011 | D38: Bag | E38: {='Cal.(DW)'!I213:J213} -> 107 | F38: 0 | G38: =IF(E38 > 0, "Yes", "No") -> Yes
A39: 20 | B39: Pipe, PVC, 25mm NPS, SCH 80, 6M Length. | C39: 01-515-432 | D39: Ea. | E39: 7 | G39: =IF(E39 > 0, "Yes", "No") -> Yes
A40: 21 | B40: Ties, Cable, 4.2mm X 360mm. (Bag of 100) | C40: 15-525-026 | D40: Ea. | E40: 5 | G40: =IF(E40 > 0, "Yes", "No") -> Yes
...
